Workbook

Sheet 汇总表
B1: FR007利率互换收盘曲线_报买:1Y | C1: FR007利率互换收盘曲线_报买:5Y | D1: FR007利率互换收盘曲线_报卖:1Y | E1: FR007利率互换收盘曲线_报卖:5Y | F1: FR007利率互换收盘曲线_均值:1Y | G1: FR007利率互换收盘曲线_均值:5Y | H1: 利率互换:FR007:1年 | I1: 利率互换:FR007:5年
A2: 频率 | B2: 日 | C2: 日 | D2: 日 | E2: 日 | F2: 日 | G2: 日 | H2: 日 | I2: 日
A3: 单位 | B3: % | C3: % | D3: % | E3: % | F3: % | G3: % | H3: % | I3: %
A4: 39497 | B4: =IFERROR(VLOOKUP($A4,原始数据_收盘!$A$4:$G$3460,2,0),"") | C4: =IFERROR(VLOOKUP($A4,原始数据_收盘!$A$4:$G$3460,3,0),"") | D4: =IFERROR(VLOOKUP($A4,原始数据_收盘!$A$4:$G$3460,4,0),"") | E4: =IFERROR(VLOOKUP($A4,原始数据_收盘!$A$4:$G$3460,5,0),"") | F4: =IFERROR(VLOOKUP($A4,原始数据_收盘!$A$4:$G$3460,6,0),"") | G4: =IFERROR(VLOOKUP($A4,原始数据_收盘!$A$4:$G$3460,7,0),"") | H4: =IFERROR(VLOOKUP($A4,原始数据_利率互换_FR007_1年!$A$6:$C$4395,2,0),"") -> 0 | I4: =IFERROR(VLOOKUP($A4,原始数据_利率互换_FR007_1年!$A$6:$C$4395,3,0),"") -> 3.59
A5: 39498 | B5: =IFERROR(VLOOKUP($A5,原始数据_收盘!$A$4:$G$3460,2,0),"") | C5: =IFERROR(VLOOKUP($A5,原始数据_收盘!$A$4:$G$3460,3,0),"") | D5: =IFERROR(VLOOKUP($A5,原始数据_收盘!$A$4:$G$3460,4,0),"") | E5: =IFERROR(VLOOKUP($A5,原始数据_收盘!$A$4:$G$3460,5,0),"") | F5: =IFERROR(VLOOKUP($A5,原始数据_收盘!$A$4:$G$3460,6,0),"") | G5: =IFERROR(VLOOKUP($A5,原始数据_收盘!$A$4:$G$3460,7,0),"") | H5: =IFERROR(VLOOKUP($A5,原始数据_利率互换_FR007_1年!$A$6:$C$4395,2,0),"") -> 3.11 | I5: =IFERROR(VLOOKUP($A5,原始数据_利率互换_FR007_1年!$A$6:$C$4395,3,0),"") -> 3.65
A6: 39499 | B6: =IFERROR(VLOOKUP($A6,原始数据_收盘!$A$4:$G$3460,2,0),"") | C6: =IFERROR(VLOOKUP($A6,原始数据_收盘!$A$4:$G$3460,3,0),"") | D6: =IFERROR(VLOOKUP($A6,原始数据_收盘!$A$4:$G$3460,4,0),"") | E6: =IFERROR(VLOOKUP($A6,原始数据_收盘!$A$4:$G$3460,5,0),"") | F6: =IFERROR(VLOOKUP($A6,原始数据_收盘!$A$4:$G$3460,6,0),"") | G6: =IFERROR(VLOOKUP($A6,原始数据_收盘!$A$4:$G$3460,7,0),"") | H6: =IFERROR(VLOOKUP($A6,原始数据_利率互换_FR007_1年!$A$6:$C$4395,2,0),"") -> 0 | I6: =IFERROR(VLOOKUP($A6,原始数据_利率互换_FR007_1年!$A$6:$C$4395,3,0),"") -> 3.67
A7: 39500 | B7: =IFERROR(VLOOKUP($A7,原始数据_收盘!$A$4:$G$3460,2,0),"") | C7: =IFERROR(VLOOKUP($A7,原始数据_收盘!$A$4:$G$3460,3,0),"") | D7: =IFERROR(VLOOKUP($A7,原始数据_收盘!$A$4:$G$3460,4,0),"") | E7: =IFERROR(VLOOKUP($A7,原始数据_收盘!$A$4:$G$3460,5,0),"") | F7: =IFERROR(VLOOKUP($A7,原始数据_收盘!$A$4:$G$3460,6,0),"") | G7: =IFERROR(VLOOKUP($A7,原始数据_收盘!$A$4:$G$3460,7,0),"") | H7: =IFERROR(VLOOKUP($A7,原始数据_利率互换_FR007_1年!$A$6:$C$4395,2,0),"") -> 3.2 | I7: =IFERROR(VLOOKUP($A7,原始数据_利率互换_FR007_1年!$A$6:$C$4395,3,0),"") -> 3.67
A8: 39501 | B8: =IFERROR(VLOOKUP($A8,原始数据_收盘!$A$4:$G$3460,2,0),"") | C8: =IFERROR(VLOOKUP($A8,原始数据_收盘!$A$4:$G$3460,3,0),"") | D8: =IFERROR(VLOOKUP($A8,原始数据_收盘!$A$4:$G$3460,4,0),"") | E8: =IFERROR(VLOOKUP($A8,原始数据_收盘!$A$4:$G$3460,5,0),"") | F8: =IFERROR(VLOOKUP($A8,原始数据_收盘!$A$4:$G$3460,6,0),"") | G8: =IFERROR(VLOOKUP($A8,原始数据_收盘!$A$4:$G$3460,7,0),"") | H8: =IFERROR(VLOOKUP($A8,原始数据_利率互换_FR007_1年!$A$6:$C$4395,2,0),"") | I8: =IFERROR(VLOOKUP($A8,原始数据_利率互换_FR007_1年!$A$6:$C$4395,3,0),"")
A9: 39502 | B9: =IFERROR(VLOOKUP($A9,原始数据_收盘!$A$4:$G$3460,2,0),"") | C9: =IFERROR(VLOOKUP($A9,原始数据_收盘!$A$4:$G$3460,3,0),"") | D9: =IFERROR(VLOOKUP($A9,原始数据_收盘!$A$4:$G$3460,4,0),"") | E9: =IFERROR(VLOOKUP($A9,原始数据_收盘!$A$4:$G$3460,5,0),"") | F9: =IFERROR(VLOOKUP($A9,原始数据_收盘!$A$4:$G$3460,6,0),"") | G9: =IFERROR(VLOOKUP($A9,原始数据_收盘!$A$4:$G$3460,7,0),"") | H9: =IFERROR(VLOOKUP($A9,原始数据_利率互换_FR007_1年!$A$6:$C$4395,2,0),"") | I9: =IFERROR(VLOOKUP($A9,原始数据_利率互换_FR007_1年!$A$6:$C$4395,3,0),"")
A10: 39503 | B10: =IFERROR(VLOOKUP($A10,原始数据_收盘!$A$4:$G$3460,2,0),"") | C10: =IFERROR(VLOOKUP($A10,原始数据_收盘!$A$4:$G$3460,3,0),"") | D10: =IFERROR(VLOOKUP($A10,原始数据_收盘!$A$4:$G$3460,4,0),"") | E10: =IFERROR(VLOOKUP($A10,原始数据_收盘!$A$4:$G$3460,5,0),"") | F10: =IFERROR(VLOOKUP($A10,原始数据_收盘!$A$4:$G$3460,6,0),"") | G10: =IFERROR(VLOOKUP($A10,原始数据_收盘!$A$4:$G$3460,7,0),"") | H10: =IFERROR(VLOOKUP($A10,原始数据_利率互换_FR007_1年!$A$6:$C$4395,2,0),"") -> 0 | I10: =IFERROR(VLOOKUP($A10,原始数据_利率互换_FR007_1年!$A$6:$C$4395,3,0),"") -> 3.615
A11: 39504 | B11: =IFERROR(VLOOKUP($A11,原始数据_收盘!$A$4:$G$3460,2,0),"") | C11: =IFERROR(VLOOKUP($A11,原始数据_收盘!$A$4:$G$3460,3,0),"") | D11: =IFERROR(VLOOKUP($A11,原始数据_收盘!$A$4:$G$3460,4,0),"") | E11: =IFERROR(VLOOKUP($A11,原始数据_收盘!$A$4:$G$3460,5,0),"") | F11: =IFERROR(VLOOKUP($A11,原始数据_收盘!$A$4:$G$3460,6,0),"") | G11: =IFERROR(VLOOKUP($A11,原始数据_收盘!$A$4:$G$3460,7,0),"") | H11: =IFERROR(VLOOKUP($A11,原始数据_利率互换_FR007_1年!$A$6:$C$4395,2,0),"") -> 3.17 | I11: =IFERROR(VLOOKUP($A11,原始数据_利率互换_FR007_1年!$A$6:$C$4395,3,0),"") -> 3.55
A12: 39505 | B12: =IFERROR(VLOOKUP($A12,原始数据_收盘!$A$4:$G$3460,2,0),"") | C12: =IFERROR(VLOOKUP($A12,原始数据_收盘!$A$4:$G$3460,3,0),"") | D12: =IFERROR(VLOOKUP($A12,原始数据_收盘!$A$4:$G$3460,4,0),"") | E12: =IFERROR(VLOOKUP($A12,原始数据_收盘!$A$4:$G$3460,5,0),"") | F12: =IFERROR(VLOOKUP($A12,原始数据_收盘!$A$4:$G$3460,6,0),"") | G12: =IFERROR(VLOOKUP($A12,原始数据_收盘!$A$4:$G$3460,7,0),"") | H12: =IFERROR(VLOOKUP($A12,原始数据_利率互换_FR007_1年!$A$6:$C$4395,2,0),"") -> 3.1 | I12: =IFERROR(VLOOKUP($A12,原始数据_利率互换_FR007_1年!$A$6:$C$4395,3,0),"") -> 3.54
A13: 39506 | B13: =IFERROR(VLOOKUP($A13,原始数据_收盘!$A$4:$G$3460,2,0),"") | C13: =IFERROR(VLOOKUP($A13,原始数据_收盘!$A$4:$G$3460,3,0),"") | D13: =IFERROR(VLOOKUP($A13,原始数据_收盘!$A$4:$G$3460,4,0),"") | E13: =IFERROR(VLOOKUP($A13,原始数据_收盘!$A$4:$G$3460,5,0),"") | F13: =IFERROR(VLOOKUP($A13,原始数据_收盘!$A$4:$G$3460,6,0),"") | G13: =IFERROR(VLOOKUP($A13,原始数据_收盘!$A$4:$G$3460,7,0),"") | H13: =IFERROR(VLOOKUP($A13,原始数据_利率互换_FR007_1年!$A$6:$C$4395,2,0),"") -> 3.1 | I13: =IFERROR(VLOOKUP($A13,原始数据_利率互换_FR007_1年!$A$6:$C$4395,3,0),"") -> 3.56
A14: 39507 | B14: =IFERROR(VLOOKUP($A14,原始数据_收盘!$A$4:$G$3460,2,0),"") | C14: =IFERROR(VLOOKUP($A14,原始数据_收盘!$A$4:$G$3460,3,0),"") | D14: =IFERROR(VLOOKUP($A14,原始数据_收盘!$A$4:$G$3460,4,0),"") | E14: =IFERROR(VLOOKUP($A14,原始数据_收盘!$A$4:$G$3460,5,0),"") | F14: =IFERROR(VLOOKUP($A14,原始数据_收盘!$A$4:$G$3460,6,0),"") | G14: =IFERROR(VLOOKUP($A14,原始数据_收盘!$A$4:$G$3460,7,0),"") | H14: =IFERROR(VLOOKUP($A14,原始数据_利率互换_FR007_1年!$A$6:$C$4395,2,0),"") -> 0 | I14: =IFERROR(VLOOKUP($A14,原始数据_利率互换_FR007_1年!$A$6:$C$4395,3,0),"") -> 3.56
A15: 39508 | B15: =IFERROR(VLOOKUP($A15,原始数据_收盘!$A$4:$G$3460,2,0),"") | C15: =IFERROR(VLOOKUP($A15,原始数据_收盘!$A$4:$G$3460,3,0),"") | D15: =IFERROR(VLOOKUP($A15,原始数据_收盘!$A$4:$G$3460,4,0),"") | E15: =IFERROR(VLOOKUP($A15,原始数据_收盘!$A$4:$G$3460,5,0),"") | F15: =IFERROR(VLOOKUP($A15,原始数据_收盘!$A$4:$G$3460,6,0),"") | G15: =IFERROR(VLOOKUP($A15,原始数据_收盘!$A$4:$G$3460,7,0),"") | H15: =IFERROR(VLOOKUP($A15,原始数据_利率互换_FR007_1年!$A$6:$C$4395,2,0),"") | I15: =IFERROR(VLOOKUP($A15,原始数据_利率互换_FR007_1年!$A$6:$C$4395,3,0),"")
... A6615: 46108 | B6615: =IFERROR(VLOOKUP($A6615,原始数据_收盘!$A$4:$G$3460,2,0),"") -> 1.515 | C6615: =IFERROR(VLOOKUP($A6615,原始数据_收盘!$A$4:$G$3460,3,0),"") -> 1.6375 | D6615: =IFERROR(VLOOKUP($A6615,原始数据_收盘!$A$4:$G$3460,4,0),"") -> 1.5175 | E6615: =IFERROR(VLOOKUP($A6615,原始数据_收盘!$A$4:$G$3460,5,0),"") -> 1.64 | F6615: =IFERROR(VLOOKUP($A6615,原始数据_收盘!$A$4:$G$3460,6,0),"") -> 1.5163 | G6615: =IFERROR(VLOOKUP($A6615,原始数据_收盘!$A$4:$G$3460,7,0),"") -> 1.6388 | H6615: =IFERROR(VLOOKUP($A6615,原始数据_利率互换_FR007_1年!$A$6:$C$4395,2,0),"") -> 1.5154 | I6615: =IFERROR(VLOOKUP($A6615,原始数据_利率互换_FR007_1年!$A$6:$C$4395,3,0),"") -> 1.6413

Sheet 原始数据_利率互换_FR007_1年
A1: 指标名称 | B1: 利率互换:FR007:1年 | C1: 利率互换:FR007:5年
A2: 频率 | B2: 日 | C2: 日
A3: 单位 | B3: % | C3: %
A4: 指标ID | B4: M0048486 | C4: M0048490
A5: 来源 | B5: 中国货币网 | C5: 中国货币网
A6: 39497 | C6: 3.59
A7: 39498 | B7: 3.11 | C7: 3.65
A8: 39499 | C8: 3.67
A9: 39500 | B9: 3.2 | C9: 3.67
A10: 39503 | C10: 3.615
A11: 39504 | B11: 3.17 | C11: 3.55
A12: 39505 | B12: 3.1 | C12: 3.54
A13: 39506 | B13: 3.1 | C13: 3.56
A14: 39507 | C14: 3.56
A15: 39510 | B15: 3.16 | C15: 3.59
A16: 39511 | B16: 3.15
A17: 39512 | B17: 3.14
A18: 39513 | B18: 3.15 | C18: 3.61
A19: 39514 | B19: 3.14 | C19: 3.62
A20: 39517 | C20: 3.66
A21: 39518 | B21: 3.12 | C21: 3.65
A22: 39519 | C22: 3.615
A23: 39521 | B23: 3.16 | C23: 3.63
A24: 39524 | B24: 3.16 | C24: 3.58
A25: 39525 | B25: 3.11
A26: 39526 | C26: 3.55
A27: 39527 | B27: 3.09 | C27: 3.42
A28: 39528 | B28: 3.08 | C28: 3.5
A29: 39532 | B29: 3.08
A30: 39533 | B30: 3.07 | C30: 3.44
A31: 39534 | B31: 3.06 | C31: 3.44
A32: 39535 | B32: 3.09
A33: 39539 | B33: 3.1
A34: 39540 | B34: 3.1 | C34: 3.5
A35: 39541 | B35: 3.1
A36: 39545 | B36: 3.12 | C36: 3.54
A37: 39546 | C37: 3.58
A38: 39547 | C38: 3.58
A39: 39548 | B39: 3.08 | C39: 3.57
A40: 39549 | B40: 3.05
...

Sheet 原始数据_收盘
B1: FR007利率互换收盘曲线_报买:1Y | C1: FR007利率互换收盘曲线_报买:5Y | D1: FR007利率互换收盘曲线_报卖:1Y | E1: FR007利率互换收盘曲线_报卖:5Y | F1: FR007利率互换收盘曲线_均值:1Y | G1: FR007利率互换收盘曲线_均值:5Y
A2: 频率 | B2: 日 | C2: 日 | D2: 日 | E2: 日 | F2: 日 | G2: 日
A3: 单位 | B3: % | C3: % | D3: % | E3: % | F3: % | G3: %
A4: 41050 | B4: 2.7355 | C4: 2.9953 | D4: 2.7951 | E4: 3.0625 | F4: 2.7653 | G4: 3.0289
A5: 41051 | B5: 2.7992 | C5: 3.0362 | D5: 2.8537 | E5: 3.0986 | F5: 2.8264 | G5: 3.0674
A6: 41052 | B6: 2.6911 | C6: 2.9707 | D6: 2.7482 | E6: 3.0396 | F6: 2.7196 | G6: 3.0052
A7: 41053 | B7: 2.4582 | C7: 2.7518 | D7: 2.5213 | E7: 2.8286 | F7: 2.4897 | G7: 2.7902
A8: 41054 | B8: 2.4734 | C8: 2.7736 | D8: 2.5321 | E8: 2.8434 | F8: 2.5028 | G8: 2.8085
A9: 41057 | B9: 2.5386 | C9: 2.8527 | D9: 2.6005 | E9: 2.9141 | F9: 2.5695 | G9: 2.8834
A10: 41058 | B10: 2.5838 | C10: 2.8696 | D10: 2.6363 | E10: 2.935 | F10: 2.61 | G10: 2.9023
A11: 41059 | B11: 2.5267 | C11: 2.833 | D11: 2.5881 | E11: 2.9016 | F11: 2.5574 | G11: 2.8673
A12: 41060 | B12: 2.4289 | C12: 2.7371 | D12: 2.4846 | E12: 2.7988 | F12: 2.4567 | G12: 2.7679
A13: 41061 | B13: 2.3969 | C13: 2.7158 | D13: 2.4558 | E13: 2.7796 | F13: 2.4263 | G13: 2.7477
A14: 41064 | B14: 2.3846 | C14: 2.6873 | D14: 2.4435 | E14: 2.7496 | F14: 2.414 | G14: 2.7185
A15: 41065 | B15: 2.4425 | C15: 2.7462 | D15: 2.4963 | E15: 2.8117 | F15: 2.4694 | G15: 2.7789
... A3460: 46108 | B3460: 1.515 | C3460: 1.6375 | D3460: 1.5175 | E3460: 1.64 | F3460: 1.5163 | G3460: 1.6388

Sheet 说明
A1: 利率互换曲线编制方案如下：
A2: 利率互换曲线由全国银行间同业拆借中心编制和发布。
A3: 利率互换曲线分为利率互换定盘/收盘曲线和利率互换行情曲线。Shibor3M和FR007利率互换曲线包括利率互换定盘/收盘曲线和利率互换行情曲线，FDR001、FDR007、ShiborO/N、LPR1Y（季付）、LPR5Y（季付）利率互换曲线包括利率互换定盘/收盘曲线。
A4: 一、利率互換定盘/收盘曲线
A5: 利率互换定盘/收盘曲线种类与期限：
A6: 利率互换定盘/收盘曲线数据样本是X-Swap报价。定盘曲线取样时间为11:45-12:00，收盘取样时间为16:15-16:30。
A7: 计算规则：在取样时间段每隔30秒选取一个取样点（例如收盘曲线取样点为16:15:30，16:16:00，....16:30:00），每个取样点选取X-Swap报价，计算出每个取样点的报买、报卖和均值价格。对30个取样点按均值排序并过滤上下各25％价格后，将剩余报价按照报买和报卖价差倒数为权重加权，计算出可成交报价的报买、报卖和均值利率。
A8: 发布时间：每个工作日12:10发布当日利率互换定盘曲线，16:40发布当日利率互换收盘曲线。每类曲线发布报买，报卖和均值三条曲线。
A10: M0048486和M0048490，为每日收盘后的FR007不同期限的加权平均价
